WARNING:root:Table the "PublishingHouse", new entry created:   АСТ-ПРЕСС
WARNING:root:Table the "Author", new entry created: Василий Егоров Петрович

INFO:django.utils.autoreload:C:\drf\apps\acount\viewsets.py changed, reloading.
INFO:django.utils.autoreload:C:\drf\apps\acount\viewsets.py changed, reloading.
INFO:django.utils.autoreload:C:\drf\apps\acount\viewsets.py changed, reloading.
WARNING:django.request:Not Found: /
WARNING:django.request:Not Found: /favicon.ico
WARNING:django.request:Not Found: /acount
WARNING:django.request:Not Found: /acount/api/v2/user
WARNING:django.request:Not Found: /acount/api/v2/user
WARNING:django.request:Not Found: /acount/api/v2/user/User
ERROR:django.request:Internal Server Error: /acount/api/v2/User/
Traceback (most recent call last):
  File "C:\drf\venv\lib\site-packages\django\core\handlers\exception.py", line 55, in inner
    response = get_response(request)
  File "C:\drf\venv\lib\site-packages\django\core\handlers\base.py", line 220, in _get_response
    response = response.render()
  File "C:\drf\venv\lib\site-packages\django\template\response.py", line 114, in render
    self.content = self.rendered_content
  File "C:\drf\venv\lib\site-packages\rest_framework\response.py", line 70, in rendered_content
    ret = renderer.render(self.data, accepted_media_type, context)
  File "C:\drf\venv\lib\site-packages\rest_framework\renderers.py", line 724, in render
    context = self.get_context(data, accepted_media_type, renderer_context)
  File "C:\drf\venv\lib\site-packages\rest_framework\renderers.py", line 680, in get_context
    'content': self.get_content(renderer, data, accepted_media_type, renderer_context),
  File "C:\drf\venv\lib\site-packages\rest_framework\renderers.py", line 413, in get_content
    content = renderer.render(data, accepted_media_type, renderer_context)
  File "C:\drf\venv\lib\site-packages\rest_framework\renderers.py", line 100, in render
    ret = json.dumps(
  File "C:\drf\venv\lib\site-packages\rest_framework\utils\json.py", line 25, in dumps
    return json.dumps(*args, **kwargs)
  File "C:\Users\W01F\AppData\Local\Programs\Python\Python38\lib\json\__init__.py", line 234, in dumps
    return cls(
  File "C:\Users\W01F\AppData\Local\Programs\Python\Python38\lib\json\encoder.py", line 201, in encode
    chunks = list(chunks)
  File "C:\Users\W01F\AppData\Local\Programs\Python\Python38\lib\json\encoder.py", line 429, in _iterencode
    yield from _iterencode_list(o, _current_indent_level)
  File "C:\Users\W01F\AppData\Local\Programs\Python\Python38\lib\json\encoder.py", line 325, in _iterencode_list
    yield from chunks
  File "C:\Users\W01F\AppData\Local\Programs\Python\Python38\lib\json\encoder.py", line 405, in _iterencode_dict
    yield from chunks
  File "C:\Users\W01F\AppData\Local\Programs\Python\Python38\lib\json\encoder.py", line 438, in _iterencode
    o = _default(o)
  File "C:\drf\venv\lib\site-packages\rest_framework\utils\encoders.py", line 67, in default
    return super().default(obj)
  File "C:\Users\W01F\AppData\Local\Programs\Python\Python38\lib\json\encoder.py", line 179, in default
    raise TypeError(f'Object of type {o.__class__.__name__} '
TypeError: Object of type Role is not JSON serializable
WARNING:django.request:Not Found: /acount/api/v2/User/
WARNING:django.request:Not Found: /acount/api/v/User/
WARNING:django.request:Not Found: /acount/api/v2/User/
INFO:django.utils.autoreload:C:\drf\apps\acount\router.py changed, reloading.
INFO:django.utils.autoreload:C:\drf\apps\acount\viewsets.py changed, reloading.
INFO:django.utils.autoreload:C:\drf\apps\acount\viewsets.py changed, reloading.
INFO:django.utils.autoreload:C:\drf\apps\acount\viewsets.py changed, reloading.
INFO:django.utils.autoreload:C:\drf\apps\acount\viewsets.py changed, reloading.
INFO:django.utils.autoreload:C:\drf\apps\acount\viewsets.py changed, reloading.
INFO:django.utils.autoreload:C:\drf\apps\acount\router.py changed, reloading.
INFO:django.utils.autoreload:C:\drf\apps\acount\serializer.py changed, reloading.
INFO:django.utils.autoreload:C:\drf\apps\acount\urls.py changed, reloading.
INFO:django.utils.autoreload:C:\drf\apps\acount\urls.py changed, reloading.
WARNING:django.request:Method Not Allowed: /acount/users/
INFO:django.utils.autoreload:C:\drf\apps\acount\urls.py changed, reloading.
INFO:django.utils.autoreload:C:\drf\apps\acount\urls.py changed, reloading.
WARNING:django.request:Method Not Allowed: /acount/users/
WARNING:django.request:Bad Request: /acount/users/
WARNING:django.request:Bad Request: /acount/users/
WARNING:django.request:Bad Request: /acount/users/
WARNING:django.request:Bad Request: /acount/users/
INFO:django.utils.autoreload:C:\drf\apps\books\serializers.py changed, reloading.
WARNING:django.request:Bad Request: /acount/users/
WARNING:django.request:Bad Request: /acount/users/
WARNING:django.request:Bad Request: /acount/users/
WARNING:django.request:Not Found: /acount/user
ERROR:django.request:Internal Server Error: /acount/users/
Traceback (most recent call last):
  File "C:\drf\venv\lib\site-packages\django\core\handlers\exception.py", line 55, in inner
    response = get_response(request)
  File "C:\drf\venv\lib\site-packages\django\core\handlers\base.py", line 220, in _get_response
    response = response.render()
  File "C:\drf\venv\lib\site-packages\django\template\response.py", line 114, in render
    self.content = self.rendered_content
  File "C:\drf\venv\lib\site-packages\rest_framework\response.py", line 70, in rendered_content
    ret = renderer.render(self.data, accepted_media_type, context)
  File "C:\drf\venv\lib\site-packages\rest_framework\renderers.py", line 724, in render
    context = self.get_context(data, accepted_media_type, renderer_context)
  File "C:\drf\venv\lib\site-packages\rest_framework\renderers.py", line 696, in get_context
    'post_form': self.get_rendered_html_form(data, view, 'POST', request),
  File "C:\drf\venv\lib\site-packages\rest_framework\renderers.py", line 511, in get_rendered_html_form
    return self.render_form_for_serializer(serializer)
  File "C:\drf\venv\lib\site-packages\rest_framework\renderers.py", line 519, in render_form_for_serializer
    serializer.data,
  File "C:\drf\venv\lib\site-packages\rest_framework\serializers.py", line 555, in data
    ret = super().data
  File "C:\drf\venv\lib\site-packages\rest_framework\serializers.py", line 257, in data
    self._data = self.get_initial()
  File "C:\drf\venv\lib\site-packages\rest_framework\serializers.py", line 405, in get_initial
    for field in self.fields.values()
  File "C:\drf\venv\lib\site-packages\django\utils\functional.py", line 49, in __get__
    res = instance.__dict__[self.name] = self.func(instance)
  File "C:\drf\venv\lib\site-packages\rest_framework\serializers.py", line 356, in fields
    for key, value in self.get_fields().items():
  File "C:\drf\venv\lib\site-packages\rest_framework\serializers.py", line 1076, in get_fields
    field_class, field_kwargs = self.build_field(
  File "C:\drf\venv\lib\site-packages\rest_framework\serializers.py", line 1222, in build_field
    return self.build_unknown_field(field_name, model_class)
  File "C:\drf\venv\lib\site-packages\rest_framework\serializers.py", line 1340, in build_unknown_field
    raise ImproperlyConfigured(
django.core.exceptions.ImproperlyConfigured: Field name `username` is not valid for model `User`.
INFO:django.utils.autoreload:C:\drf\apps\acount\urls.py changed, reloading.
WARNING:django.request:Not Found: /acount/users/
WARNING:django.request:Not Found: /acount/users/
INFO:django.utils.autoreload:C:\drf\apps\acount\serializer.py changed, reloading.
INFO:django.utils.autoreload:C:\drf\apps\acount\serializer.py changed, reloading.
WARNING:django.request:Not Found: /acount/users/
WARNING:django.request:Not Found: /acount/users/
WARNING:django.request:Not Found: /acount/users/
WARNING:django.request:Not Found: /acount/users/
WARNING:django.request:Not Found: /acount/users/
INFO:django.utils.autoreload:C:\drf\apps\acount\serializer.py changed, reloading.
WARNING:django.request:Not Found: /acount/users/
WARNING:django.request:Not Found: /acount/users/
INFO:django.utils.autoreload:C:\drf\apps\acount\urls.py changed, reloading.
WARNING:django.request:Method Not Allowed: /acount/users/
INFO:django.utils.autoreload:C:\drf\apps\acount\serializer.py changed, reloading.
ERROR:django.request:Internal Server Error: /acount/users/
Traceback (most recent call last):
  File "C:\drf\venv\lib\site-packages\django\core\handlers\exception.py", line 55, in inner
    response = get_response(request)
  File "C:\drf\venv\lib\site-packages\django\core\handlers\base.py", line 220, in _get_response
    response = response.render()
  File "C:\drf\venv\lib\site-packages\django\template\response.py", line 114, in render
    self.content = self.rendered_content
  File "C:\drf\venv\lib\site-packages\rest_framework\response.py", line 70, in rendered_content
    ret = renderer.render(self.data, accepted_media_type, context)
  File "C:\drf\venv\lib\site-packages\rest_framework\renderers.py", line 724, in render
    context = self.get_context(data, accepted_media_type, renderer_context)
  File "C:\drf\venv\lib\site-packages\rest_framework\renderers.py", line 696, in get_context
    'post_form': self.get_rendered_html_form(data, view, 'POST', request),
  File "C:\drf\venv\lib\site-packages\rest_framework\renderers.py", line 511, in get_rendered_html_form
    return self.render_form_for_serializer(serializer)
  File "C:\drf\venv\lib\site-packages\rest_framework\renderers.py", line 519, in render_form_for_serializer
    serializer.data,
  File "C:\drf\venv\lib\site-packages\rest_framework\serializers.py", line 555, in data
    ret = super().data
  File "C:\drf\venv\lib\site-packages\rest_framework\serializers.py", line 257, in data
    self._data = self.get_initial()
  File "C:\drf\venv\lib\site-packages\rest_framework\serializers.py", line 405, in get_initial
    for field in self.fields.values()
  File "C:\drf\venv\lib\site-packages\django\utils\functional.py", line 49, in __get__
    res = instance.__dict__[self.name] = self.func(instance)
  File "C:\drf\venv\lib\site-packages\rest_framework\serializers.py", line 356, in fields
    for key, value in self.get_fields().items():
  File "C:\drf\venv\lib\site-packages\rest_framework\serializers.py", line 1076, in get_fields
    field_class, field_kwargs = self.build_field(
  File "C:\drf\venv\lib\site-packages\rest_framework\serializers.py", line 1222, in build_field
    return self.build_unknown_field(field_name, model_class)
  File "C:\drf\venv\lib\site-packages\rest_framework\serializers.py", line 1340, in build_unknown_field
    raise ImproperlyConfigured(
django.core.exceptions.ImproperlyConfigured: Field name `username` is not valid for model `User`.
INFO:django.utils.autoreload:C:\drf\apps\acount\serializer.py changed, reloading.
ERROR:django.request:Internal Server Error: /acount/users/
Traceback (most recent call last):
  File "C:\drf\venv\lib\site-packages\django\core\handlers\exception.py", line 55, in inner
    response = get_response(request)
  File "C:\drf\venv\lib\site-packages\django\core\handlers\base.py", line 220, in _get_response
    response = response.render()
  File "C:\drf\venv\lib\site-packages\django\template\response.py", line 114, in render
    self.content = self.rendered_content
  File "C:\drf\venv\lib\site-packages\rest_framework\response.py", line 70, in rendered_content
    ret = renderer.render(self.data, accepted_media_type, context)
  File "C:\drf\venv\lib\site-packages\rest_framework\renderers.py", line 724, in render
    context = self.get_context(data, accepted_media_type, renderer_context)
  File "C:\drf\venv\lib\site-packages\rest_framework\renderers.py", line 696, in get_context
    'post_form': self.get_rendered_html_form(data, view, 'POST', request),
  File "C:\drf\venv\lib\site-packages\rest_framework\renderers.py", line 511, in get_rendered_html_form
    return self.render_form_for_serializer(serializer)
  File "C:\drf\venv\lib\site-packages\rest_framework\renderers.py", line 519, in render_form_for_serializer
    serializer.data,
  File "C:\drf\venv\lib\site-packages\rest_framework\serializers.py", line 555, in data
    ret = super().data
  File "C:\drf\venv\lib\site-packages\rest_framework\serializers.py", line 257, in data
    self._data = self.get_initial()
  File "C:\drf\venv\lib\site-packages\rest_framework\serializers.py", line 405, in get_initial
    for field in self.fields.values()
  File "C:\drf\venv\lib\site-packages\django\utils\functional.py", line 49, in __get__
    res = instance.__dict__[self.name] = self.func(instance)
  File "C:\drf\venv\lib\site-packages\rest_framework\serializers.py", line 356, in fields
    for key, value in self.get_fields().items():
  File "C:\drf\venv\lib\site-packages\rest_framework\serializers.py", line 1076, in get_fields
    field_class, field_kwargs = self.build_field(
  File "C:\drf\venv\lib\site-packages\rest_framework\serializers.py", line 1222, in build_field
    return self.build_unknown_field(field_name, model_class)
  File "C:\drf\venv\lib\site-packages\rest_framework\serializers.py", line 1340, in build_unknown_field
    raise ImproperlyConfigured(
django.core.exceptions.ImproperlyConfigured: Field name `username` is not valid for model `User`.
INFO:django.utils.autoreload:C:\drf\apps\acount\serializer.py changed, reloading.
INFO:django.utils.autoreload:C:\drf\apps\acount\serializer.py changed, reloading.
WARNING:django.request:Method Not Allowed: /acount/users/
WARNING:django.request:Bad Request: /acount/users/
WARNING:django.request:Bad Request: /acount/users/
INFO:django.utils.autoreload:C:\drf\apps\acount\serializer.py changed, reloading.
WARNING:django.request:Not Found: /
WARNING:django.request:Not Found: /accounts/login/
INFO:django.utils.autoreload:C:\drf\library\settings.py changed, reloading.
INFO:django.utils.autoreload:C:\drf\library\settings.py changed, reloading.
WARNING:django.request:Not Found: /books/
WARNING:django.server:"GET /books/ HTTP/1.1" 404 2624
WARNING:django.request:Not Found: /favicon.ico
WARNING:django.server:"GET /favicon.ico HTTP/1.1" 404 2585
INFO:django.server:"GET /swagger HTTP/1.1" 301 0
INFO:django.server:"GET /swagger/ HTTP/1.1" 200 2159
INFO:django.server:"GET /static/drf-yasg/style.css HTTP/1.1" 200 1047
INFO:django.server:"GET /static/drf-yasg/swagger-ui-dist/swagger-ui.css HTTP/1.1" 200 143858
INFO:django.server:"GET /static/drf-yasg/swagger-ui-dist/swagger-ui-bundle.js HTTP/1.1" 200 1086481
INFO:django.server:"GET /static/drf-yasg/insQ.min.js HTTP/1.1" 200 2093
INFO:django.server:"GET /static/drf-yasg/immutable.min.js HTTP/1.1" 200 56904
INFO:django.server:"GET /static/drf-yasg/swagger-ui-init.js HTTP/1.1" 200 14964
INFO:django.server:"GET /static/drf-yasg/swagger-ui-dist/swagger-ui-standalone-preset.js HTTP/1.1" 200 324275
INFO:django.server:"GET /swagger/?format=openapi HTTP/1.1" 200 8660
INFO:django.server:"GET /static/drf-yasg/swagger-ui-dist/favicon-32x32.png HTTP/1.1" 200 628
WARNING:django.request:Bad Request: /acount/users/
WARNING:django.server:"POST /acount/users/ HTTP/1.1" 400 115
WARNING:django.request:Not Found: /
WARNING:django.server:"GET / HTTP/1.1" 404 2534
WARNING:django.request:Not Found: /books
WARNING:django.server:"GET /books HTTP/1.1" 404 2567
WARNING:django.request:Not Found: /qweqwew
WARNING:django.server:"GET /qweqwew HTTP/1.1" 404 2573
WARNING:django.request:Bad Request: /acount/users/
WARNING:django.server:"POST /acount/users/ HTTP/1.1" 400 115
INFO:django.server:"GET /swagger/ HTTP/1.1" 200 2159
INFO:django.server:"GET /swagger/?format=openapi HTTP/1.1" 200 8660
WARNING:django.request:Bad Request: /acount/users/
WARNING:django.server:"POST /acount/users/ HTTP/1.1" 400 115
WARNING:django.request:Not Found: /books
WARNING:django.server:"GET /books HTTP/1.1" 404 2567
INFO:django.server:"GET /swagger/ HTTP/1.1" 200 2159
INFO:django.server:"GET /swagger/?format=openapi HTTP/1.1" 200 8660
INFO:django.utils.autoreload:C:\drf\library\settings.py changed, reloading.
INFO:django.utils.autoreload:C:\drf\library\settings.py changed, reloading.
INFO:django.utils.autoreload:C:\drf\library\settings.py changed, reloading.
INFO:django.utils.autoreload:C:\drf\library\settings.py changed, reloading.
INFO:django.utils.autoreload:C:\drf\library\settings.py changed, reloading.
INFO:django.utils.autoreload:C:\drf\library\settings.py changed, reloading.
INFO:django.utils.autoreload:C:\drf\library\settings.py changed, reloading.
INFO:django.utils.autoreload:C:\drf\library\settings.py changed, reloading.
WARNING:django.request:Bad Request: /acount/users/
WARNING:django.server:"POST /acount/users/ HTTP/1.1" 400 115
WARNING:django.request:Not Found: /books
WARNING:django.server:"GET /books HTTP/1.1" 404 2567
WARNING:django.request:Not Found: /favicon.ico
WARNING:django.server:"GET /favicon.ico HTTP/1.1" 404 2585
WARNING:django.request:Not Found: /books/swagger
WARNING:django.server:"GET /books/swagger HTTP/1.1" 404 2645
WARNING:django.request:Not Found: /
WARNING:django.server:"GET / HTTP/1.1" 404 2534
WARNING:django.request:Bad Request: /acount/users/
WARNING:django.server:"POST /acount/users/ HTTP/1.1" 400 115
WARNING:django.request:Bad Request: /acount/users/
WARNING:django.server:"POST /acount/users/ HTTP/1.1" 400 115
WARNING:django.request:Bad Request: /acount/users/
WARNING:django.server:"POST /acount/users/ HTTP/1.1" 400 115
WARNING:django.request:Bad Request: /acount/users/
WARNING:django.server:"POST /acount/users/ HTTP/1.1" 400 115
WARNING:kombu.connection:No hostname was supplied. Reverting to default 'localhost'
ERROR:django.request:Internal Server Error: /books/api/v1/pub_house/
Traceback (most recent call last):
  File "C:\drf\venv\lib\site-packages\kombu\utils\functional.py", line 30, in __call__
    return self.__value__
AttributeError: 'ChannelPromise' object has no attribute '__value__'

During handling of the above exception, another exception occurred:

Traceback (most recent call last):
  File "C:\drf\venv\lib\site-packages\kombu\connection.py", line 446, in _reraise_as_library_errors
    yield
  File "C:\drf\venv\lib\site-packages\kombu\connection.py", line 433, in _ensure_connection
    return retry_over_time(
  File "C:\drf\venv\lib\site-packages\kombu\utils\functional.py", line 312, in retry_over_time
    return fun(*args, **kwargs)
  File "C:\drf\venv\lib\site-packages\kombu\connection.py", line 877, in _connection_factory
    self._connection = self._establish_connection()
  File "C:\drf\venv\lib\site-packages\kombu\connection.py", line 812, in _establish_connection
    conn = self.transport.establish_connection()
  File "C:\drf\venv\lib\site-packages\kombu\transport\pyamqp.py", line 201, in establish_connection
    conn.connect()
  File "C:\drf\venv\lib\site-packages\amqp\connection.py", line 323, in connect
    self.transport.connect()
  File "C:\drf\venv\lib\site-packages\amqp\transport.py", line 129, in connect
    self._connect(self.host, self.port, self.connect_timeout)
  File "C:\drf\venv\lib\site-packages\amqp\transport.py", line 184, in _connect
    self.sock.connect(sa)
ConnectionRefusedError: [WinError 10061] Подключение не установлено, т.к. конечный компьютер отверг запрос на подключение

The above exception was the direct cause of the following exception:

Traceback (most recent call last):
  File "C:\drf\venv\lib\site-packages\django\core\handlers\exception.py", line 55, in inner
    response = get_response(request)
  File "C:\drf\venv\lib\site-packages\django\core\handlers\base.py", line 197, in _get_response
    response = wrapped_callback(request, *callback_args, **callback_kwargs)
  File "C:\drf\venv\lib\site-packages\django\views\decorators\csrf.py", line 54, in wrapped_view
    return view_func(*args, **kwargs)
  File "C:\drf\venv\lib\site-packages\rest_framework\viewsets.py", line 125, in view
    return self.dispatch(request, *args, **kwargs)
  File "C:\drf\venv\lib\site-packages\rest_framework\views.py", line 509, in dispatch
    response = self.handle_exception(exc)
  File "C:\drf\venv\lib\site-packages\rest_framework\views.py", line 469, in handle_exception
    self.raise_uncaught_exception(exc)
  File "C:\drf\venv\lib\site-packages\rest_framework\views.py", line 480, in raise_uncaught_exception
    raise exc
  File "C:\drf\venv\lib\site-packages\rest_framework\views.py", line 506, in dispatch
    response = handler(request, *args, **kwargs)
  File "C:\drf\apps\books\viewsets.py", line 26, in create
    inform_new.delay()
  File "C:\drf\venv\lib\site-packages\celery\app\task.py", line 425, in delay
    return self.apply_async(args, kwargs)
  File "C:\drf\venv\lib\site-packages\celery\app\task.py", line 575, in apply_async
    return app.send_task(
  File "C:\drf\venv\lib\site-packages\celery\app\base.py", line 788, in send_task
    amqp.send_task_message(P, name, message, **options)
  File "C:\drf\venv\lib\site-packages\celery\app\amqp.py", line 510, in send_task_message
    ret = producer.publish(
  File "C:\drf\venv\lib\site-packages\kombu\messaging.py", line 177, in publish
    return _publish(
  File "C:\drf\venv\lib\site-packages\kombu\connection.py", line 523, in _ensured
    return fun(*args, **kwargs)
  File "C:\drf\venv\lib\site-packages\kombu\messaging.py", line 186, in _publish
    channel = self.channel
  File "C:\drf\venv\lib\site-packages\kombu\messaging.py", line 209, in _get_channel
    channel = self._channel = channel()
  File "C:\drf\venv\lib\site-packages\kombu\utils\functional.py", line 32, in __call__
    value = self.__value__ = self.__contract__()
  File "C:\drf\venv\lib\site-packages\kombu\messaging.py", line 225, in <lambda>
    channel = ChannelPromise(lambda: connection.default_channel)
  File "C:\drf\venv\lib\site-packages\kombu\connection.py", line 895, in default_channel
    self._ensure_connection(**conn_opts)
  File "C:\drf\venv\lib\site-packages\kombu\connection.py", line 433, in _ensure_connection
    return retry_over_time(
  File "C:\Users\W01F\AppData\Local\Programs\Python\Python38\lib\contextlib.py", line 131, in __exit__
    self.gen.throw(type, value, traceback)
  File "C:\drf\venv\lib\site-packages\kombu\connection.py", line 450, in _reraise_as_library_errors
    raise ConnectionError(str(exc)) from exc
kombu.exceptions.OperationalError: [WinError 10061] Подключение не установлено, т.к. конечный компьютер отверг запрос на подключение
ERROR:django.server:"POST /books/api/v1/pub_house/ HTTP/1.1" 500 21101
ERROR:django.request:Internal Server Error: /books/api/v1/pub_house/
Traceback (most recent call last):
  File "C:\drf\venv\lib\site-packages\django\core\handlers\exception.py", line 55, in inner
    response = get_response(request)
  File "C:\drf\venv\lib\site-packages\django\core\handlers\base.py", line 197, in _get_response
    response = wrapped_callback(request, *callback_args, **callback_kwargs)
  File "C:\drf\venv\lib\site-packages\django\views\decorators\csrf.py", line 54, in wrapped_view
    return view_func(*args, **kwargs)
  File "C:\drf\venv\lib\site-packages\rest_framework\viewsets.py", line 125, in view
    return self.dispatch(request, *args, **kwargs)
  File "C:\drf\venv\lib\site-packages\rest_framework\views.py", line 509, in dispatch
    response = self.handle_exception(exc)
  File "C:\drf\venv\lib\site-packages\rest_framework\views.py", line 469, in handle_exception
    self.raise_uncaught_exception(exc)
  File "C:\drf\venv\lib\site-packages\rest_framework\views.py", line 480, in raise_uncaught_exception
    raise exc
  File "C:\drf\venv\lib\site-packages\rest_framework\views.py", line 506, in dispatch
    response = handler(request, *args, **kwargs)
TypeError: 'NoneType' object is not callable
ERROR:django.server:"POST /books/api/v1/pub_house/ HTTP/1.1" 500 17388
ERROR:django.request:Internal Server Error: /books/api/v1/pub_house/
Traceback (most recent call last):
  File "C:\drf\venv\lib\site-packages\django\core\handlers\exception.py", line 55, in inner
    response = get_response(request)
  File "C:\drf\venv\lib\site-packages\django\core\handlers\base.py", line 197, in _get_response
    response = wrapped_callback(request, *callback_args, **callback_kwargs)
  File "C:\drf\venv\lib\site-packages\django\views\decorators\csrf.py", line 54, in wrapped_view
    return view_func(*args, **kwargs)
  File "C:\drf\venv\lib\site-packages\rest_framework\viewsets.py", line 125, in view
    return self.dispatch(request, *args, **kwargs)
  File "C:\drf\venv\lib\site-packages\rest_framework\views.py", line 509, in dispatch
    response = self.handle_exception(exc)
  File "C:\drf\venv\lib\site-packages\rest_framework\views.py", line 469, in handle_exception
    self.raise_uncaught_exception(exc)
  File "C:\drf\venv\lib\site-packages\rest_framework\views.py", line 480, in raise_uncaught_exception
    raise exc
  File "C:\drf\venv\lib\site-packages\rest_framework\views.py", line 506, in dispatch
    response = handler(request, *args, **kwargs)
TypeError: 'NoneType' object is not callable
ERROR:django.server:"POST /books/api/v1/pub_house/ HTTP/1.1" 500 17388
WARNING:django.request:Not Found: /books/book/
WARNING:django.server:"POST /books/book/ HTTP/1.1" 404 2640
WARNING:django.request:Not Found: /news/
WARNING:django.server:"GET /news/ HTTP/1.1" 404 2460
WARNING:django.request:Not Found: /favicon.ico
WARNING:django.server:"GET /favicon.ico HTTP/1.1" 404 2478
WARNING:drf_yasg.inspectors.base:view's PublishingHouseViewSet raised exception during schema generation; use `getattr(self, 'swagger_fake_view', False)` to detect and short-circuit this
Traceback (most recent call last):
  File "C:\drf\venv\lib\site-packages\drf_yasg\inspectors\base.py", line 42, in call_view_method
    return view_method()
  File "C:\drf\venv\lib\site-packages\rest_framework\generics.py", line 108, in get_serializer
    serializer_class = self.get_serializer_class()
  File "C:\drf\venv\lib\site-packages\rest_framework\generics.py", line 122, in get_serializer_class
    assert self.serializer_class is not None, (
AssertionError: 'PublishingHouseViewSet' should either include a `serializer_class` attribute, or override the `get_serializer_class()` method.
WARNING:drf_yasg.inspectors.base:view's PublishingHouseViewSet raised exception during schema generation; use `getattr(self, 'swagger_fake_view', False)` to detect and short-circuit this
Traceback (most recent call last):
  File "C:\drf\venv\lib\site-packages\drf_yasg\inspectors\base.py", line 42, in call_view_method
    return view_method()
  File "C:\drf\venv\lib\site-packages\rest_framework\generics.py", line 108, in get_serializer
    serializer_class = self.get_serializer_class()
  File "C:\drf\venv\lib\site-packages\rest_framework\generics.py", line 122, in get_serializer_class
    assert self.serializer_class is not None, (
AssertionError: 'PublishingHouseViewSet' should either include a `serializer_class` attribute, or override the `get_serializer_class()` method.
WARNING:drf_yasg.inspectors.base:view's PublishingHouseViewSet raised exception during schema generation; use `getattr(self, 'swagger_fake_view', False)` to detect and short-circuit this
Traceback (most recent call last):
  File "C:\drf\venv\lib\site-packages\drf_yasg\inspectors\base.py", line 42, in call_view_method
    return view_method()
  File "C:\drf\venv\lib\site-packages\rest_framework\generics.py", line 108, in get_serializer
    serializer_class = self.get_serializer_class()
  File "C:\drf\venv\lib\site-packages\rest_framework\generics.py", line 122, in get_serializer_class
    assert self.serializer_class is not None, (
AssertionError: 'PublishingHouseViewSet' should either include a `serializer_class` attribute, or override the `get_serializer_class()` method.
WARNING:drf_yasg.inspectors.base:view's PublishingHouseViewSet raised exception during schema generation; use `getattr(self, 'swagger_fake_view', False)` to detect and short-circuit this
Traceback (most recent call last):
  File "C:\drf\venv\lib\site-packages\drf_yasg\inspectors\base.py", line 42, in call_view_method
    return view_method()
  File "C:\drf\venv\lib\site-packages\rest_framework\generics.py", line 108, in get_serializer
    serializer_class = self.get_serializer_class()
  File "C:\drf\venv\lib\site-packages\rest_framework\generics.py", line 122, in get_serializer_class
    assert self.serializer_class is not None, (
AssertionError: 'PublishingHouseViewSet' should either include a `serializer_class` attribute, or override the `get_serializer_class()` method.
WARNING:drf_yasg.inspectors.base:view's PublishingHouseViewSet raised exception during schema generation; use `getattr(self, 'swagger_fake_view', False)` to detect and short-circuit this
Traceback (most recent call last):
  File "C:\drf\venv\lib\site-packages\drf_yasg\inspectors\base.py", line 42, in call_view_method
    return view_method()
  File "C:\drf\venv\lib\site-packages\rest_framework\generics.py", line 108, in get_serializer
    serializer_class = self.get_serializer_class()
  File "C:\drf\venv\lib\site-packages\rest_framework\generics.py", line 122, in get_serializer_class
    assert self.serializer_class is not None, (
AssertionError: 'PublishingHouseViewSet' should either include a `serializer_class` attribute, or override the `get_serializer_class()` method.
WARNING:drf_yasg.inspectors.base:view's PublishingHouseViewSet raised exception during schema generation; use `getattr(self, 'swagger_fake_view', False)` to detect and short-circuit this
Traceback (most recent call last):
  File "C:\drf\venv\lib\site-packages\drf_yasg\inspectors\base.py", line 42, in call_view_method
    return view_method()
  File "C:\drf\venv\lib\site-packages\rest_framework\generics.py", line 108, in get_serializer
    serializer_class = self.get_serializer_class()
  File "C:\drf\venv\lib\site-packages\rest_framework\generics.py", line 122, in get_serializer_class
    assert self.serializer_class is not None, (
AssertionError: 'PublishingHouseViewSet' should either include a `serializer_class` attribute, or override the `get_serializer_class()` method.
WARNING:drf_yasg.inspectors.base:view's PublishingHouseViewSet raised exception during schema generation; use `getattr(self, 'swagger_fake_view', False)` to detect and short-circuit this
Traceback (most recent call last):
  File "C:\drf\venv\lib\site-packages\drf_yasg\inspectors\base.py", line 42, in call_view_method
    return view_method()
  File "C:\drf\venv\lib\site-packages\rest_framework\generics.py", line 108, in get_serializer
    serializer_class = self.get_serializer_class()
  File "C:\drf\venv\lib\site-packages\rest_framework\generics.py", line 122, in get_serializer_class
    assert self.serializer_class is not None, (
AssertionError: 'PublishingHouseViewSet' should either include a `serializer_class` attribute, or override the `get_serializer_class()` method.
WARNING:drf_yasg.inspectors.base:view's PublishingHouseViewSet raised exception during schema generation; use `getattr(self, 'swagger_fake_view', False)` to detect and short-circuit this
Traceback (most recent call last):
  File "C:\drf\venv\lib\site-packages\drf_yasg\inspectors\base.py", line 42, in call_view_method
    return view_method()
  File "C:\drf\venv\lib\site-packages\rest_framework\generics.py", line 108, in get_serializer
    serializer_class = self.get_serializer_class()
  File "C:\drf\venv\lib\site-packages\rest_framework\generics.py", line 122, in get_serializer_class
    assert self.serializer_class is not None, (
AssertionError: 'PublishingHouseViewSet' should either include a `serializer_class` attribute, or override the `get_serializer_class()` method.
ERROR:django.request:Internal Server Error: /books/api/v1/pub_house/
Traceback (most recent call last):
  File "C:\drf\venv\lib\site-packages\django\core\handlers\exception.py", line 55, in inner
    response = get_response(request)
  File "C:\drf\venv\lib\site-packages\django\core\handlers\base.py", line 197, in _get_response
    response = wrapped_callback(request, *callback_args, **callback_kwargs)
  File "C:\drf\venv\lib\site-packages\django\views\decorators\csrf.py", line 54, in wrapped_view
    return view_func(*args, **kwargs)
  File "C:\drf\venv\lib\site-packages\rest_framework\viewsets.py", line 125, in view
    return self.dispatch(request, *args, **kwargs)
  File "C:\drf\venv\lib\site-packages\rest_framework\views.py", line 509, in dispatch
    response = self.handle_exception(exc)
  File "C:\drf\venv\lib\site-packages\rest_framework\views.py", line 469, in handle_exception
    self.raise_uncaught_exception(exc)
  File "C:\drf\venv\lib\site-packages\rest_framework\views.py", line 480, in raise_uncaught_exception
    raise exc
  File "C:\drf\venv\lib\site-packages\rest_framework\views.py", line 506, in dispatch
    response = handler(request, *args, **kwargs)
TypeError: create() missing 1 required positional argument: 'pk'
ERROR:django.server:"POST /books/api/v1/pub_house/ HTTP/1.1" 500 17328
WARNING:django.request:Not Found: /pub_house
WARNING:django.server:"GET /pub_house HTTP/1.1" 404 2472
WARNING:django.request:Not Found: /api/v1/pub_house
WARNING:django.server:"GET /api/v1/pub_house HTTP/1.1" 404 2493
ERROR:django.request:Internal Server Error: /books/api/v1/pub_house/
Traceback (most recent call last):
  File "C:\drf\venv\lib\site-packages\django\core\handlers\exception.py", line 55, in inner
    response = get_response(request)
  File "C:\drf\venv\lib\site-packages\django\core\handlers\base.py", line 220, in _get_response
    response = response.render()
  File "C:\drf\venv\lib\site-packages\django\template\response.py", line 114, in render
    self.content = self.rendered_content
  File "C:\drf\venv\lib\site-packages\rest_framework\response.py", line 70, in rendered_content
    ret = renderer.render(self.data, accepted_media_type, context)
  File "C:\drf\venv\lib\site-packages\rest_framework\renderers.py", line 724, in render
    context = self.get_context(data, accepted_media_type, renderer_context)
  File "C:\drf\venv\lib\site-packages\rest_framework\renderers.py", line 655, in get_context
    raw_data_post_form = self.get_raw_data_form(data, view, 'POST', request)
  File "C:\drf\venv\lib\site-packages\rest_framework\renderers.py", line 554, in get_raw_data_form
    serializer = view.get_serializer()
  File "C:\drf\venv\lib\site-packages\rest_framework\generics.py", line 108, in get_serializer
    serializer_class = self.get_serializer_class()
  File "C:\drf\venv\lib\site-packages\rest_framework\generics.py", line 122, in get_serializer_class
    assert self.serializer_class is not None, (
AssertionError: 'PublishingHouseViewSet' should either include a `serializer_class` attribute, or override the `get_serializer_class()` method.
ERROR:django.server:"GET /books/api/v1/pub_house/ HTTP/1.1" 500 104334
ERROR:django.request:Internal Server Error: /books/api/v1/pub_house
Traceback (most recent call last):
  File "C:\drf\venv\lib\site-packages\django\core\handlers\exception.py", line 55, in inner
    response = get_response(request)
  File "C:\drf\venv\lib\site-packages\django\utils\deprecation.py", line 133, in __call__
    response = self.process_request(request)
  File "C:\drf\venv\lib\site-packages\django\middleware\common.py", line 54, in process_request
    path = self.get_full_path_with_slash(request)
  File "C:\drf\venv\lib\site-packages\django\middleware\common.py", line 88, in get_full_path_with_slash
    raise RuntimeError(
RuntimeError: You called this URL via POST, but the URL doesn't end in a slash and you have APPEND_SLASH set. Django can't redirect to the slash URL while maintaining POST data. Change your form to point to 127.0.0.1:8000/books/api/v1/pub_house/ (note the trailing slash), or set APPEND_SLASH=False in your Django settings.
ERROR:django.server:"POST /books/api/v1/pub_house HTTP/1.1" 500 69302
ERROR:django.request:Internal Server Error: /books/api/v1/pub_house
Traceback (most recent call last):
  File "C:\drf\venv\lib\site-packages\django\core\handlers\exception.py", line 55, in inner
    response = get_response(request)
  File "C:\drf\venv\lib\site-packages\django\utils\deprecation.py", line 133, in __call__
    response = self.process_request(request)
  File "C:\drf\venv\lib\site-packages\django\middleware\common.py", line 54, in process_request
    path = self.get_full_path_with_slash(request)
  File "C:\drf\venv\lib\site-packages\django\middleware\common.py", line 88, in get_full_path_with_slash
    raise RuntimeError(
RuntimeError: You called this URL via POST, but the URL doesn't end in a slash and you have APPEND_SLASH set. Django can't redirect to the slash URL while maintaining POST data. Change your form to point to 127.0.0.1:8000/books/api/v1/pub_house/ (note the trailing slash), or set APPEND_SLASH=False in your Django settings.
ERROR:django.server:"POST /books/api/v1/pub_house HTTP/1.1" 500 69302
ERROR:django.request:Internal Server Error: /books/api/v1/pub_house
Traceback (most recent call last):
  File "C:\drf\venv\lib\site-packages\django\core\handlers\exception.py", line 55, in inner
    response = get_response(request)
  File "C:\drf\venv\lib\site-packages\django\utils\deprecation.py", line 133, in __call__
    response = self.process_request(request)
  File "C:\drf\venv\lib\site-packages\django\middleware\common.py", line 54, in process_request
    path = self.get_full_path_with_slash(request)
  File "C:\drf\venv\lib\site-packages\django\middleware\common.py", line 88, in get_full_path_with_slash
    raise RuntimeError(
RuntimeError: You called this URL via POST, but the URL doesn't end in a slash and you have APPEND_SLASH set. Django can't redirect to the slash URL while maintaining POST data. Change your form to point to 127.0.0.1:8000/books/api/v1/pub_house/ (note the trailing slash), or set APPEND_SLASH=False in your Django settings.
ERROR:django.server:"POST /books/api/v1/pub_house HTTP/1.1" 500 69302
ERROR:django.request:Internal Server Error: /books/api/v1/pub_house
Traceback (most recent call last):
  File "C:\drf\venv\lib\site-packages\django\core\handlers\exception.py", line 55, in inner
    response = get_response(request)
  File "C:\drf\venv\lib\site-packages\django\utils\deprecation.py", line 133, in __call__
    response = self.process_request(request)
  File "C:\drf\venv\lib\site-packages\django\middleware\common.py", line 54, in process_request
    path = self.get_full_path_with_slash(request)
  File "C:\drf\venv\lib\site-packages\django\middleware\common.py", line 88, in get_full_path_with_slash
    raise RuntimeError(
RuntimeError: You called this URL via POST, but the URL doesn't end in a slash and you have APPEND_SLASH set. Django can't redirect to the slash URL while maintaining POST data. Change your form to point to 127.0.0.1:8000/books/api/v1/pub_house/ (note the trailing slash), or set APPEND_SLASH=False in your Django settings.
ERROR:django.server:"POST /books/api/v1/pub_house HTTP/1.1" 500 69302
ERROR:django.request:Internal Server Error: /books/api/v1/pub_house
Traceback (most recent call last):
  File "C:\drf\venv\lib\site-packages\django\core\handlers\exception.py", line 55, in inner
    response = get_response(request)
  File "C:\drf\venv\lib\site-packages\django\utils\deprecation.py", line 133, in __call__
    response = self.process_request(request)
  File "C:\drf\venv\lib\site-packages\django\middleware\common.py", line 54, in process_request
    path = self.get_full_path_with_slash(request)
  File "C:\drf\venv\lib\site-packages\django\middleware\common.py", line 88, in get_full_path_with_slash
    raise RuntimeError(
RuntimeError: You called this URL via POST, but the URL doesn't end in a slash and you have APPEND_SLASH set. Django can't redirect to the slash URL while maintaining POST data. Change your form to point to 127.0.0.1:8000/books/api/v1/pub_house/ (note the trailing slash), or set APPEND_SLASH=False in your Django settings.
ERROR:django.server:"POST /books/api/v1/pub_house HTTP/1.1" 500 69302
ERROR:django.request:Internal Server Error: /books/api/v1/pub_house
Traceback (most recent call last):
  File "C:\drf\venv\lib\site-packages\django\core\handlers\exception.py", line 55, in inner
    response = get_response(request)
  File "C:\drf\venv\lib\site-packages\django\utils\deprecation.py", line 133, in __call__
    response = self.process_request(request)
  File "C:\drf\venv\lib\site-packages\django\middleware\common.py", line 54, in process_request
    path = self.get_full_path_with_slash(request)
  File "C:\drf\venv\lib\site-packages\django\middleware\common.py", line 88, in get_full_path_with_slash
    raise RuntimeError(
RuntimeError: You called this URL via POST, but the URL doesn't end in a slash and you have APPEND_SLASH set. Django can't redirect to the slash URL while maintaining POST data. Change your form to point to 127.0.0.1:8000/books/api/v1/pub_house/ (note the trailing slash), or set APPEND_SLASH=False in your Django settings.
ERROR:django.server:"POST /books/api/v1/pub_house HTTP/1.1" 500 69302
ERROR:django.request:Internal Server Error: /books/api/v1/pub_house
Traceback (most recent call last):
  File "C:\drf\venv\lib\site-packages\django\core\handlers\exception.py", line 55, in inner
    response = get_response(request)
  File "C:\drf\venv\lib\site-packages\django\utils\deprecation.py", line 133, in __call__
    response = self.process_request(request)
  File "C:\drf\venv\lib\site-packages\django\middleware\common.py", line 54, in process_request
    path = self.get_full_path_with_slash(request)
  File "C:\drf\venv\lib\site-packages\django\middleware\common.py", line 88, in get_full_path_with_slash
    raise RuntimeError(
RuntimeError: You called this URL via POST, but the URL doesn't end in a slash and you have APPEND_SLASH set. Django can't redirect to the slash URL while maintaining POST data. Change your form to point to 127.0.0.1:8000/books/api/v1/pub_house/ (note the trailing slash), or set APPEND_SLASH=False in your Django settings.
ERROR:django.server:"POST /books/api/v1/pub_house HTTP/1.1" 500 69302
WARNING:django.request:Not Found: /books/api/v1/pub_house
WARNING:django.server:"POST /books/api/v1/pub_house HTTP/1.1" 404 6079
WARNING:django.request:Not Found: /books/api/v1/pub_house
WARNING:django.server:"POST /books/api/v1/pub_house HTTP/1.1" 404 6088
WARNING:django.request:Not Found: /books/api/v1/pub_house
WARNING:django.server:"GET /books/api/v1/pub_house HTTP/1.1" 404 6087
WARNING:django.request:Not Found: /books/api/v1/pub_house
WARNING:django.server:"GET /books/api/v1/pub_house HTTP/1.1" 404 6087
WARNING:django.request:Not Found: /books/api/v1/pub_house
WARNING:django.server:"POST /books/api/v1/pub_house HTTP/1.1" 404 6088
WARNING:django.request:Not Found: /books/api/v1/pub_house
WARNING:django.server:"POST /books/api/v1/pub_house HTTP/1.1" 404 6088
WARNING:django.request:Not Found: /books/api/v1/pub_house
WARNING:django.server:"POST /books/api/v1/pub_house HTTP/1.1" 404 6088
WARNING:django.request:Not Found: /books/api/v1/pub_house
WARNING:django.server:"POST /books/api/v1/pub_house HTTP/1.1" 404 6088
WARNING:django.request:Not Found: /books/api/v1/pub_house
WARNING:django.server:"POST /books/api/v1/pub_house HTTP/1.1" 404 6088
WARNING:django.request:Not Found: /books/api/v1/pub_house
WARNING:django.server:"POST /books/api/v1/pub_house HTTP/1.1" 404 6088
WARNING:django.request:Not Found: /books/api/v1/pub_house
WARNING:django.server:"POST /books/api/v1/pub_house HTTP/1.1" 404 6085
WARNING:django.request:Not Found: /books/api/v1/pub_house
WARNING:django.server:"POST /books/api/v1/pub_house HTTP/1.1" 404 6085
WARNING:django.request:Not Found: /books/api/v1/pub_house
WARNING:django.server:"POST /books/api/v1/pub_house HTTP/1.1" 404 6085
WARNING:django.request:Not Found: /books/api/v1/pub_house
WARNING:django.server:"GET /books/api/v1/pub_house HTTP/1.1" 404 6084
WARNING:django.request:Not Found: /books/api/v1/pub_house
WARNING:django.server:"GET /books/api/v1/pub_house HTTP/1.1" 404 6084
